<!-- GENERATED by tools/convert_unitree_biped.py — do not hand-edit.
     Legs-only (12-DOF) unitree_g1_29dof in zealot's MJCF dialect: upper body fused
     into the pelvis, every hinge axis normalized to local +Z, link-frame
     fullinertia, sole contact capsules on the ankle_roll links. -->
<mujoco model="unitree_g1_29dof">
  <compiler angle="radian"/>
  <default>
    <default class="collision"/>
  </default>
  <worldbody>
    <body name="pelvis" pos="0 0 0.793" quat="1 0 0 0">
      <inertial pos="0 0 -0.07605" mass="3.813" fullinertia="0.0105489983 0.0093089 0.00791840168 0 2.09999645e-06 0"/>
      <freejoint/>
      <body name="left_hip_pitch_link" pos="0 0.064452 -0.1027" quat="0.707106781 -0.707106781 0 0">
        <inertial pos="0.002741 0.02606 0.047791" mass="1.35" fullinertia="0.00181100487 0.00128120214 0.00141930299 3.44002e-05 3.68000839e-05 -0.000171000371"/>
        <joint name="left_hip_pitch_joint" axis="0 0 1" range="-2.5307 2.8798"/>
        <body name="left_hip_roll_link" pos="0 0.030465 0.052" quat="0.541758629 0.541758629 0.454420057 0.454420057">
          <inertial pos="0.087934 -0.001045 0.029812" mass="1.52" fullinertia="0.0016595016 0.00241229823 0.00237730017 -1.84000462e-05 0.00039079999 -3.80016636e-06"/>
          <joint name="left_hip_roll_joint" axis="0 0 1" range="-0.5236 2.9671"/>
          <body name="left_hip_yaw_link" pos="0.12412 0 0.025001" quat="0.707106781 0 -0.707106781 0">
            <inertial pos="-0.057709 -0.010981 -0.15078" mass="1.702" fullinertia="0.00577739711 0.0076124014 0.00314900149 -0.000541101155 -0.00239480377 -0.00070720225"/>
            <joint name="left_hip_yaw_joint" axis="0 0 1" range="-2.7576 2.7576"/>
            <body name="left_knee_link" pos="-0.078273 0.0021489 -0.17734" quat="0.704404704 -0.704404704 0.0617576968 0.0617576968">
              <inertial pos="0.005457 0.12074 0.003964" mass="1.932" fullinertia="0.0113289923 0.00151679526 0.0112769924 4.48974521e-05 4.81665062e-05 0.000714600249"/>
              <joint name="left_knee_joint" axis="0 0 1" range="-0.087267 2.8798"/>
              <body name="left_ankle_pitch_link" pos="0 0.30001 -9.4445e-05" quat="1 0 0 0">
                <inertial pos="-0.007269 -0.011137 1.73472348e-18" mass="0.074" fullinertia="8.39999715e-06 1.26000028e-05 1.89e-05 2.89999453e-06 -5.33097347e-22 5.29511238e-22"/>
                <joint name="left_ankle_pitch_joint" axis="0 0 1" range="-0.87267 0.5236"/>
                <body name="left_ankle_roll_link" pos="0 0.017558 -3.46944695e-18" quat="0.5 0.5 0.5 0.5">
                  <inertial pos="0.016425 0 0.026505" mass="0.608" fullinertia="0.00166670122 0.00161610011 0.000223099671 1.00002017e-07 -8.91010117e-05 1.99999908e-07"/>
                  <joint name="left_ankle_roll_joint" axis="0 0 1" range="-0.2618 0.2618"/>
                  <geom class="collision" fromto="0.03 -0.03 -0.05 0.03 -0.03 0.12" size="0.005"/>
                  <geom class="collision" fromto="0.03 0.03 -0.05 0.03 0.03 0.12" size="0.005"/>
                </body>
              </body>
            </body>
          </body>
        </body>
      </body>
      <body name="right_hip_pitch_link" pos="0 -0.064452 -0.1027" quat="0.707106781 -0.707106781 0 0">
        <inertial pos="0.002741 0.02606 -0.047791" mass="1.35" fullinertia="0.00181100487 0.00128120214 0.00141930299 3.44002e-05 -3.68000839e-05 0.000171000371"/>
        <joint name="right_hip_pitch_joint" axis="0 0 1" range="-2.5307 2.8798"/>
        <body name="right_hip_roll_link" pos="0 0.030465 -0.052" quat="0.541758629 0.541758629 0.454420057 0.454420057">
          <inertial pos="0.087934 0.001045 0.029812" mass="1.52" fullinertia="0.0016595016 0.00241229823 0.00237730017 1.84000462e-05 0.00039079999 3.80016636e-06"/>
          <joint name="right_hip_roll_joint" axis="0 0 1" range="-2.9671 0.5236"/>
          <body name="right_hip_yaw_link" pos="0.12412 0 0.025001" quat="0.707106781 0 -0.707106781 0">
            <inertial pos="-0.057709 0.010981 -0.15078" mass="1.702" fullinertia="0.00577739711 0.0076124014 0.00314900149 0.000541101155 -0.00239480377 0.00070720225"/>
            <joint name="right_hip_yaw_joint" axis="0 0 1" range="-2.7576 2.7576"/>
            <body name="right_knee_link" pos="-0.078273 -0.0021489 -0.17734" quat="0.704404704 -0.704404704 0.0617576968 0.0617576968">
              <inertial pos="0.005457 0.12074 -0.003964" mass="1.932" fullinertia="0.0113290107 0.00151679887 0.0112770104 -4.48973458e-05 -4.82389719e-05 -0.000714601046"/>
              <joint name="right_knee_joint" axis="0 0 1" range="-0.087267 2.8798"/>
              <body name="right_ankle_pitch_link" pos="0 0.30001 9.4445e-05" quat="1 0 0 0">
                <inertial pos="-0.007269 -0.011137 1.73472348e-18" mass="0.074" fullinertia="8.39999715e-06 1.26000028e-05 1.89e-05 2.89999453e-06 -5.33097347e-22 5.29511238e-22"/>
                <joint name="right_ankle_pitch_joint" axis="0 0 1" range="-0.87267 0.5236"/>
                <body name="right_ankle_roll_link" pos="0 0.017558 -3.46944695e-18" quat="0.5 0.5 0.5 0.5">
                  <inertial pos="0.016425 0 0.026505" mass="0.608" fullinertia="0.00166670122 0.00161610011 0.000223099671 -1.00002017e-07 -8.91010117e-05 -1.99999908e-07"/>
                  <joint name="right_ankle_roll_joint" axis="0 0 1" range="-0.2618 0.2618"/>
                  <geom class="collision" fromto="0.03 -0.03 -0.05 0.03 -0.03 0.12" size="0.005"/>
                  <geom class="collision" fromto="0.03 0.03 -0.05 0.03 0.03 0.12" size="0.005"/>
                </body>
              </body>
            </body>
          </body>
        </body>
      </body>
      <body name="waist_yaw_link" pos="0 0 0" quat="1 0 0 0">
        <inertial pos="0.003494 0.000233 0.018034" mass="0.214" fullinertia="0.000106729754 0.000104219847 0.000162500399 2.70281413e-06 -7.63111886e-06 -2.00997774e-07"/>
        <joint name="waist_yaw_joint" axis="0 0 1" range="-2.618 2.618"/>
        <body name="waist_roll_link" pos="-0.0039635 0 0.044" quat="0.707106781 0 0.707106781 0">
          <inertial pos="0 2.3e-05 0" mass="0.086" fullinertia="8.245e-06 6.339e-06 7.079e-06 0 -1.83072781e-22 0"/>
          <joint name="waist_roll_joint" axis="0 0 1" range="-0.52 0.52"/>
          <body name="torso_link" pos="0 0 0" quat="0.5 -0.5 -0.5 -0.5">
            <inertial pos="0.00203158 -0.184568 0.000339683" mass="7.818" fullinertia="0.121698443 0.0275219757 0.109825081 0.00374228948 3.11092566e-05 1.55074339e-05"/>
            <joint name="waist_pitch_joint" axis="0 0 1" range="-0.52 0.52"/>
            <body name="left_shoulder_pitch_link" pos="0.0039563 -0.24778 0.10022" quat="0.99026414 0.13920102 9.86868139e-05 1.3872202e-05">
              <inertial pos="0 0.011628 0.035892" mass="0.718" fullinertia="0.000429099685 0.000423000059 0.000453000256 -6.39978351e-06 -9.20001783e-06 -2.26001111e-05"/>
              <joint name="left_shoulder_pitch_joint" axis="0 0 1" range="-3.0892 2.6704"/>
              <body name="left_shoulder_roll_link" pos="0 0.013831 0.038" quat="0.564720125 0.425548094 0.564720125 0.425548094">
                <inertial pos="0.063243 0.00727 -0.000227" mass="0.643" fullinertia="0.000389399553 0.000691199832 0.000617699615 5.30032372e-06 -8.69999998e-06 -1.00008224e-06"/>
                <joint name="left_shoulder_roll_joint" axis="0 0 1" range="-1.5882 2.2515"/>
                <body name="left_shoulder_yaw_link" pos="0.1032 0.00624 -2.08166817e-17" quat="0.707106781 0 -0.707106781 0">
                  <inertial pos="0.010773 -0.002949 -0.072009" mass="0.734" fullinertia="0.000998803887 0.00106049671 0.000435400401 7.89971003e-06 0.000141200796 -2.85999284e-05"/>
                  <joint name="left_shoulder_yaw_joint" axis="0 0 1" range="-2.618 2.618"/>
                  <body name="left_elbow_link" pos="0.015783 0 -0.080518" quat="0.707106781 -0.707106781 0 0">
                    <inertial pos="0.064956 0.010062 0.004454" mass="0.6" fullinertia="0.000289099621 0.000419700405 0.000415199974 -1.7200109e-05 6.53001523e-05 5.60008769e-06"/>
                    <joint name="left_elbow_joint" axis="0 0 1" range="-1.0472 2.0944"/>
                    <body name="left_wrist_roll_link" pos="0.1 0.01 0.00188791" quat="0.5 0.5 0.5 0.5">
                      <inertial pos="-0.0166433536 0.0411473531 0.0391169174" mass="0.824071" fullinertia="0.00229913482 0.00174245645 0.00118083738 -0.000139552412 -0.000160561434 -0.000588482481"/>
                      <joint name="left_wrist_roll_joint" axis="0 0 1" range="-1.97222 1.97222"/>
                    </body>
                  </body>
                </body>
              </body>
            </body>
            <body name="right_shoulder_pitch_link" pos="0.0039563 -0.24778 -0.10021" quat="0.99026414 -0.13920102 -9.86868139e-05 1.3872202e-05">
              <inertial pos="0 0.011628 -0.035892" mass="0.718" fullinertia="0.000429099685 0.000423000059 0.000453000256 -6.39978351e-06 9.20001783e-06 2.26001111e-05"/>
              <joint name="right_shoulder_pitch_joint" axis="0 0 1" range="-3.0892 2.6704"/>
              <body name="right_shoulder_roll_link" pos="0 0.013831 -0.038" quat="0.425548094 0.564720125 0.425548094 0.564720125">
                <inertial pos="0.063243 -0.00727 -0.000227" mass="0.643" fullinertia="0.000389399553 0.000691199832 0.000617699615 -5.30032372e-06 -8.69999998e-06 1.00008224e-06"/>
                <joint name="right_shoulder_roll_joint" axis="0 0 1" range="-2.2515 1.5882"/>
                <body name="right_shoulder_yaw_link" pos="0.1032 -0.00624 -2.08166817e-17" quat="0.707106781 0 -0.707106781 0">
                  <inertial pos="0.010773 0.002949 -0.072009" mass="0.734" fullinertia="0.000998803887 0.00106049671 0.000435400401 -7.89971003e-06 0.000141200796 2.85999284e-05"/>
                  <joint name="right_shoulder_yaw_joint" axis="0 0 1" range="-2.618 2.618"/>
                  <body name="right_elbow_link" pos="0.015783 0 -0.080518" quat="0.707106781 -0.707106781 0 0">
                    <inertial pos="0.064956 0.010062 -0.004454" mass="0.6" fullinertia="0.000289099621 0.000419700405 0.000415199974 -1.7200109e-05 -6.53001523e-05 -5.60008769e-06"/>
                    <joint name="right_elbow_joint" axis="0 0 1" range="-1.0472 2.0944"/>
                    <body name="right_wrist_roll_link" pos="0.1 0.01 -0.00188791" quat="0.5 0.5 0.5 0.5">
                      <inertial pos="0.0169556629 0.0422294518 0.0352159255" mass="0.824071" fullinertia="0.00204963002 0.0015689087 0.00119200236 0.000176421643 0.000141789835 -0.00047836843"/>
                      <joint name="right_wrist_roll_joint" axis="0 0 1" range="-1.97222 1.97222"/>
                    </body>
                  </body>
                </body>
              </body>
            </body>
          </body>
        </body>
      </body>
    </body>
  </worldbody>
</mujoco>
