<!-- GENERATED by tools/convert_unitree_biped.py — do not hand-edit.
     Legs-only (12-DOF) unitree_g1_12dof in zealot's MJCF dialect: upper body fused
     into the pelvis, every hinge axis normalized to local +Z, link-frame
     fullinertia, sole contact capsules on the ankle_roll links. -->
<mujoco model="unitree_g1_12dof">
  <compiler angle="radian"/>
  <default>
    <default class="collision"/>
  </default>
  <worldbody>
    <body name="pelvis" pos="0 0 0.793" quat="1 0 0 0">
      <inertial pos="0.0144905 0.000151462 0.144068" mass="17.7349" fullinertia="0.55239842 0.454091802 0.212086778 7.37641619e-05 0.0105141997 -0.000240370252"/>
      <freejoint/>
      <body name="left_hip_pitch_link" pos="0 0.064452 -0.1027" quat="0.707106781 -0.707106781 0 0">
        <inertial pos="0.002741 0.02606 0.047791" mass="1.35" fullinertia="0.00181100487 0.00128120214 0.00141930299 3.44002e-05 3.68000839e-05 -0.000171000371"/>
        <joint name="left_hip_pitch_joint" axis="0 0 1" range="-2.5307 2.8798" damping="0.001" armature="0.01"/>
        <body name="left_hip_roll_link" pos="0 0.030465 0.052" quat="0.541758629 0.541758629 0.454420057 0.454420057">
          <inertial pos="0.087934 -0.001045 0.029812" mass="1.52" fullinertia="0.0016595016 0.00241229823 0.00237730017 -1.84000462e-05 0.00039079999 -3.80016636e-06"/>
          <joint name="left_hip_roll_joint" axis="0 0 1" range="-0.5236 2.9671" damping="0.001" armature="0.01"/>
          <body name="left_hip_yaw_link" pos="0.12412 0 0.025001" quat="0.707106781 0 -0.707106781 0">
            <inertial pos="-0.057709 -0.010981 -0.15078" mass="1.702" fullinertia="0.00577739711 0.0076124014 0.00314900149 -0.000541101155 -0.00239480377 -0.00070720225"/>
            <joint name="left_hip_yaw_joint" axis="0 0 1" range="-2.7576 2.7576" damping="0.001" armature="0.01"/>
            <body name="left_knee_link" pos="-0.078273 0.0021489 -0.17734" quat="0.704404704 -0.704404704 0.0617576968 0.0617576968">
              <inertial pos="0.005457 0.12074 0.003964" mass="1.932" fullinertia="0.0113289923 0.00151679526 0.0112769924 4.48974521e-05 4.81665062e-05 0.000714600249"/>
              <joint name="left_knee_joint" axis="0 0 1" range="-0.087267 2.8798" damping="0.001" armature="0.01"/>
              <body name="left_ankle_pitch_link" pos="0 0.30001 -9.4445e-05" quat="1 0 0 0">
                <inertial pos="-0.007269 -0.011137 1.73472348e-18" mass="0.074" fullinertia="8.39999715e-06 1.26000028e-05 1.89e-05 2.89999453e-06 -5.33097347e-22 5.29511238e-22"/>
                <joint name="left_ankle_pitch_joint" axis="0 0 1" range="-0.87267 0.5236" damping="0.001" armature="0.01"/>
                <body name="left_ankle_roll_link" pos="0 0.017558 -3.46944695e-18" quat="0.5 0.5 0.5 0.5">
                  <inertial pos="0.016425 0 0.026505" mass="0.608" fullinertia="0.00166670122 0.00161610011 0.000223099671 1.00002017e-07 -8.91010117e-05 1.99999908e-07"/>
                  <joint name="left_ankle_roll_joint" axis="0 0 1" range="-0.2618 0.2618" damping="0.001" armature="0.01"/>
                  <geom class="collision" fromto="0.03 -0.03 -0.05 0.03 -0.03 0.12" size="0.005"/>
                  <geom class="collision" fromto="0.03 0.03 -0.05 0.03 0.03 0.12" size="0.005"/>
                </body>
              </body>
            </body>
          </body>
        </body>
      </body>
      <body name="right_hip_pitch_link" pos="0 -0.064452 -0.1027" quat="0.707106781 -0.707106781 0 0">
        <inertial pos="0.002741 0.02606 -0.047791" mass="1.35" fullinertia="0.00181100487 0.00128120214 0.00141930299 3.44002e-05 -3.68000839e-05 0.000171000371"/>
        <joint name="right_hip_pitch_joint" axis="0 0 1" range="-2.5307 2.8798" damping="0.001" armature="0.01"/>
        <body name="right_hip_roll_link" pos="0 0.030465 -0.052" quat="0.541758629 0.541758629 0.454420057 0.454420057">
          <inertial pos="0.087934 0.001045 0.029812" mass="1.52" fullinertia="0.0016595016 0.00241229823 0.00237730017 1.84000462e-05 0.00039079999 3.80016636e-06"/>
          <joint name="right_hip_roll_joint" axis="0 0 1" range="-2.9671 0.5236" damping="0.001" armature="0.01"/>
          <body name="right_hip_yaw_link" pos="0.12412 0 0.025001" quat="0.707106781 0 -0.707106781 0">
            <inertial pos="-0.057709 0.010981 -0.15078" mass="1.702" fullinertia="0.00577739711 0.0076124014 0.00314900149 0.000541101155 -0.00239480377 0.00070720225"/>
            <joint name="right_hip_yaw_joint" axis="0 0 1" range="-2.7576 2.7576" damping="0.001" armature="0.01"/>
            <body name="right_knee_link" pos="-0.078273 -0.0021489 -0.17734" quat="0.704404704 -0.704404704 0.0617576968 0.0617576968">
              <inertial pos="0.005457 0.12074 -0.003964" mass="1.932" fullinertia="0.0113290107 0.00151679887 0.0112770104 -4.48973458e-05 -4.82389719e-05 -0.000714601046"/>
              <joint name="right_knee_joint" axis="0 0 1" range="-0.087267 2.8798" damping="0.001" armature="0.01"/>
              <body name="right_ankle_pitch_link" pos="0 0.30001 9.4445e-05" quat="1 0 0 0">
                <inertial pos="-0.007269 -0.011137 1.73472348e-18" mass="0.074" fullinertia="8.39999715e-06 1.26000028e-05 1.89e-05 2.89999453e-06 -5.33097347e-22 5.29511238e-22"/>
                <joint name="right_ankle_pitch_joint" axis="0 0 1" range="-0.87267 0.5236" damping="0.001" armature="0.01"/>
                <body name="right_ankle_roll_link" pos="0 0.017558 -3.46944695e-18" quat="0.5 0.5 0.5 0.5">
                  <inertial pos="0.016425 0 0.026505" mass="0.608" fullinertia="0.00166670122 0.00161610011 0.000223099671 -1.00002017e-07 -8.91010117e-05 -1.99999908e-07"/>
                  <joint name="right_ankle_roll_joint" axis="0 0 1" range="-0.2618 0.2618" damping="0.001" armature="0.01"/>
                  <geom class="collision" fromto="0.03 -0.03 -0.05 0.03 -0.03 0.12" size="0.005"/>
                  <geom class="collision" fromto="0.03 0.03 -0.05 0.03 0.03 0.12" size="0.005"/>
                </body>
              </body>
            </body>
          </body>
        </body>
      </body>
    </body>
  </worldbody>
</mujoco>
