<!-- GENERATED by tools/convert_unitree_biped.py — do not hand-edit.
     Legs-only (12-DOF) unitree_h2_plus_12dof in zealot's MJCF dialect: upper body fused
     into the pelvis, every hinge axis normalized to local +Z, link-frame
     fullinertia, sole contact capsules on the ankle_roll links. -->
<mujoco model="unitree_h2_plus_12dof">
  <compiler angle="radian"/>
  <default>
    <default class="collision"/>
  </default>
  <worldbody>
    <body name="pelvis" pos="0 0 0" quat="1 0 0 0">
      <inertial pos="0.0273401879 0.0192527875 0.248356972" mass="45.0364703" fullinertia="2.52740106 2.67104319 1.55453147 -0.104789805 0.473637873 0.058063274"/>
      <freejoint/>
      <body name="left_hip_pitch_link" pos="0 0.08038 -0.046407" quat="0.49999947 -0.86602571 0 0">
        <inertial pos="0.00294368 0.01735095 0.06110195" mass="2.8737" fullinertia="0.00536755004 0.00403077 0.00387518996 -1.13804191e-05 -9.87896978e-05 -0.000248859971"/>
        <joint name="left_hip_pitch_joint" axis="0 0 1" range="-2.4525975 2.7754225"/>
        <body name="left_hip_roll_link" pos="0.041774 0.019 0.0635" quat="0.353553016 0.612372652 0.353553016 0.612372652">
          <inertial pos="0.041315 -0.00607425 -0.01757892" mass="0.78507858" fullinertia="0.00228152014 0.00203648998 0.00157951988 0.000126149995 0.000208639779 -2.65400908e-05"/>
          <joint name="left_hip_roll_joint" axis="0 0 1" range="-0.467441 2.1688605"/>
          <body name="left_hip_yaw_link" pos="0.0737 -0.0095 -0.028187" quat="0.707106781 0 -0.707106781 0">
            <inertial pos="0.00069408 -0.01086587 -0.11301456" mass="7.0875" fullinertia="0.0505800001 0.0511049999 0.013319 -5.54702341e-05 0.00146680002 -0.003122"/>
            <joint name="left_hip_yaw_joint" axis="0 0 1" range="-2.827 2.827"/>
            <body name="left_knee_link" pos="-0.010308 0.022549 -0.31959" quat="0.707106781 -0.707106781 0 0">
              <inertial pos="0.00461331 0.16715459 -0.022549" mass="4.35340244" fullinertia="0.05108514 0.00334361004 0.05123842 0.000416312035 -7.19999943e-06 -1.339e-05"/>
              <joint name="left_knee_joint" axis="0 0 1" range="-0.08725 2.53025"/>
              <body name="left_ankle_roll_link" pos="0.032719 0.49662 -0.023002" quat="0.5 0.5 0.5 0.5">
                <inertial pos="0.0002146 6.424e-05 -0.01740632" mass="0.12318157" fullinertia="4.005e-05 1.44999998e-05 3.43200002e-05 2.00000001e-08 -1.99999877e-08 1.19984347e-07"/>
                <joint name="left_ankle_roll_joint" axis="0 0 1" range="-0.34906585 0.296705973"/>
                <body name="left_ankle_pitch_link" pos="-8.67361738e-19 -0.0373 -0.014516" quat="0.5 -0.5 -0.5 -0.5">
                  <inertial pos="0.032059 0.02882818 0.03700531" mass="0.89496747" fullinertia="0.00060825 0.0043749 0.00410964 -0.000176710002 4.6e-07 1.0000001e-08"/>
                  <joint name="left_ankle_pitch_joint" axis="0 0 1" range="-1.13446401 0.610865238"/>
                  <geom class="collision" fromto="-0.0749999982 0.0493000001 -0.000152455997 0.154999996 0.0493000001 -0.000152455997" size="0.005"/>
                  <geom class="collision" fromto="-0.0749999982 0.0493000001 0.0753052112 0.154999996 0.0493000001 0.0753052112" size="0.005"/>
                </body>
              </body>
            </body>
          </body>
        </body>
      </body>
      <body name="right_hip_pitch_link" pos="0 -0.08038 -0.046407" quat="0.86602571 -0.49999947 0 0">
        <inertial pos="0.00294368 0.01735095 -0.06110195" mass="2.8737" fullinertia="0.00536755004 0.00403077 0.00387518996 -1.13804191e-05 9.87896978e-05 0.000248859971"/>
        <joint name="right_hip_pitch_joint" axis="0 0 1" range="-2.4525975 2.7754225"/>
        <body name="right_hip_roll_link" pos="0.041774 0.019 -0.0635" quat="0.612372652 0.353553016 0.612372652 0.353553016">
          <inertial pos="0.041315 0.00607425 -0.01757892" mass="0.75122" fullinertia="0.00228152014 0.00203648998 0.00157951988 -0.000126149995 0.000208639779 2.65400908e-05"/>
          <joint name="right_hip_roll_joint" axis="0 0 1" range="-2.1688605 0.467441"/>
          <body name="right_hip_yaw_link" pos="0.0737 0.0095 -0.028187" quat="0.707106781 0 -0.707106781 0">
            <inertial pos="0.00069408 0.01086587 -0.11301456" mass="7.0875" fullinertia="0.0505800001 0.0511049999 0.013319 5.54702341e-05 0.00146680002 0.003122"/>
            <joint name="right_hip_yaw_joint" axis="0 0 1" range="-2.827 2.827"/>
            <body name="right_knee_link" pos="-0.010308 -0.022549 -0.31959" quat="0.707106781 -0.707106781 0 0">
              <inertial pos="0.00461331 0.16715459 0.022549" mass="4.35340244" fullinertia="0.05108514 0.00334361004 0.05123842 0.000416312035 7.19999943e-06 1.339e-05"/>
              <joint name="right_knee_joint" axis="0 0 1" range="-0.08725 2.53025"/>
              <body name="right_ankle_roll_link" pos="0.032719 0.49662 0.023002" quat="0.5 0.5 0.5 0.5">
                <inertial pos="0.0002146 -6.424e-05 -0.01740632" mass="0.12318157" fullinertia="4.005e-05 1.44999998e-05 3.43200002e-05 -2.00000001e-08 -1.99999877e-08 -1.19984347e-07"/>
                <joint name="right_ankle_roll_joint" axis="0 0 1" range="-0.296705973 0.34906585"/>
                <body name="right_ankle_pitch_link" pos="-8.67361738e-19 0.0373 -0.014516" quat="0.5 -0.5 -0.5 -0.5">
                  <inertial pos="0.032059 0.02882818 -0.03700531" mass="0.89496747" fullinertia="0.00060825 0.0043749 0.00410964 -0.000176710002 -4.6e-07 -1.0000001e-08"/>
                  <joint name="right_ankle_pitch_joint" axis="0 0 1" range="-1.13446401 0.610865238"/>
                  <geom class="collision" fromto="-0.0749999982 0.0493000001 -0.0753052112 0.154999996 0.0493000001 -0.0753052112" size="0.005"/>
                  <geom class="collision" fromto="-0.0749999982 0.0493000001 0.000152455997 0.154999996 0.0493000001 0.000152455997" size="0.005"/>
                </body>
              </body>
            </body>
          </body>
        </body>
      </body>
    </body>
  </worldbody>
</mujoco>
